Workbook

Sheet OLTP Tables
A1: Input: OLTP Tables | C1: Output: DWH Used Tables
A2: SchemaName | B2: TableName | C2: Table Abbrev. | D2: IsUsed in DWH
A3: HumanResources | B3: Employee | C3: em. | D3: =COUNTIF('DWH Tables Metadata'!$B$5:$B$99,B3)>0 -> TRUE | E3: =IF(D3=TRUE,"Used","Not Used") -> Used
A4: Person | B4: AddressType | D4: =COUNTIF('DWH Tables Metadata'!$B$5:$B$99,B4)>0 -> FALSE | E4: =IF(D4=TRUE,"Used","Not Used") -> Not Used
A5: Person | B5: BusinessEntity | D5: =COUNTIF('DWH Tables Metadata'!$B$5:$B$99,B5)>0 -> FALSE | E5: =IF(D5=TRUE,"Used","Not Used") -> Not Used
A6: Person | B6: Address | C6: ad. | D6: =COUNTIF('DWH Tables Metadata'!$B$5:$B$99,B6)>0 -> TRUE | E6: =IF(D6=TRUE,"Used","Not Used") -> Used
A7: Person | B7: BusinessEntityAddress | D7: =COUNTIF('DWH Tables Metadata'!$B$5:$B$99,B7)>0 -> FALSE | E7: =IF(D7=TRUE,"Used","Not Used") -> Not Used
A8: Person | B8: StateProvince | C8: spr. | D8: =COUNTIF('DWH Tables Metadata'!$B$5:$B$99,B8)>0 -> TRUE | E8: =IF(D8=TRUE,"Used","Not Used") -> Used
A9: Person | B9: BusinessEntityContact | D9: =COUNTIF('DWH Tables Metadata'!$B$5:$B$99,B9)>0 -> FALSE | E9: =IF(D9=TRUE,"Used","Not Used") -> Not Used
A10: Person | B10: Person | C10: prs. | D10: =COUNTIF('DWH Tables Metadata'!$B$5:$B$99,B10)>0 -> TRUE | E10: =IF(D10=TRUE,"Used","Not Used") -> Used
A11: Person | B11: CountryRegion | C11: cr. | D11: =COUNTIF('DWH Tables Metadata'!$B$5:$B$99,B11)>0 -> TRUE | E11: =IF(D11=TRUE,"Used","Not Used") -> Used
A12: Production | B12: Location | D12: =COUNTIF('DWH Tables Metadata'!$B$5:$B$99,B12)>0 -> FALSE | E12: =IF(D12=TRUE,"Used","Not Used") -> Not Used
A13: Production | B13: ProductListPriceHistory | D13: =COUNTIF('DWH Tables Metadata'!$B$5:$B$99,B13)>0 -> FALSE | E13: =IF(D13=TRUE,"Used","Not Used") -> Not Used
A14: Production | B14: ProductModel | D14: =COUNTIF('DWH Tables Metadata'!$B$5:$B$99,B14)>0 -> FALSE | E14: =IF(D14=TRUE,"Used","Not Used") -> Not Used
A15: Production | B15: Product | C15: p. | D15: =COUNTIF('DWH Tables Metadata'!$B$5:$B$99,B15)>0 -> TRUE | E15: =IF(D15=TRUE,"Used","Not Used") -> Used
A16: Production | B16: ProductCategory | C16: pc. | D16: =COUNTIF('DWH Tables Metadata'!$B$5:$B$99,B16)>0 -> TRUE | E16: =IF(D16=TRUE,"Used","Not Used") -> Used
A17: Production | B17: ProductReview | D17: =COUNTIF('DWH Tables Metadata'!$B$5:$B$99,B17)>0 -> FALSE | E17: =IF(D17=TRUE,"Used","Not Used") -> Not Used
A18: Production | B18: ScrapReason | D18: =COUNTIF('DWH Tables Metadata'!$B$5:$B$99,B18)>0 -> FALSE | E18: =IF(D18=TRUE,"Used","Not Used") -> Not Used
A19: Production | B19: TransactionHistoryArchive | D19: =COUNTIF('DWH Tables Metadata'!$B$5:$B$99,B19)>0 -> FALSE | E19: =IF(D19=TRUE,"Used","Not Used") -> Not Used
A20: Production | B20: ProductSubcategory | C20: psc. | D20: =COUNTIF('DWH Tables Metadata'!$B$5:$B$99,B20)>0 -> TRUE | E20: =IF(D20=TRUE,"Used","Not Used") -> Used
A21: Production | B21: UnitMeasure | C21: pumW. | D21: =COUNTIF('DWH Tables Metadata'!$B$5:$B$99,B21)>0 -> TRUE | E21: =IF(D21=TRUE,"Used","Not Used") -> Used
A22: Production | B22: UnitMeasure | C22: pumS. | D22: =COUNTIF('DWH Tables Metadata'!$B$5:$B$99,B22)>0 -> TRUE | E22: =IF(D22=TRUE,"Used","Not Used") -> Used
A23: Purchasing | B23: ProductVendor | D23: =COUNTIF('DWH Tables Metadata'!$B$5:$B$99,B23)>0 -> FALSE | E23: =IF(D23=TRUE,"Used","Not Used") -> Not Used
A24: Purchasing | B24: PurchaseOrderDetail | D24: =COUNTIF('DWH Tables Metadata'!$B$5:$B$99,B24)>0 -> FALSE | E24: =IF(D24=TRUE,"Used","Not Used") -> Not Used
A25: Purchasing | B25: PurchaseOrderHeader | D25: =COUNTIF('DWH Tables Metadata'!$B$5:$B$99,B25)>0 -> FALSE | E25: =IF(D25=TRUE,"Used","Not Used") -> Not Used
A26: Purchasing | B26: Vendor | D26: =COUNTIF('DWH Tables Metadata'!$B$5:$B$99,B26)>0 -> FALSE | E26: =IF(D26=TRUE,"Used","Not Used") -> Not Used
A27: Sales | B27: CountryRegionCurrency | D27: =COUNTIF('DWH Tables Metadata'!$B$5:$B$99,B27)>0 -> FALSE | E27: =IF(D27=TRUE,"Used","Not Used") -> Not Used
A28: Sales | B28: SalesTerritory | C28: st. | D28: =COUNTIF('DWH Tables Metadata'!$B$5:$B$99,B28)>0 -> TRUE | E28: =IF(D28=TRUE,"Used","Not Used") -> Used
A29: Sales | B29: Currency | D29: =COUNTIF('DWH Tables Metadata'!$B$5:$B$99,B29)>0 -> FALSE | E29: =IF(D29=TRUE,"Used","Not Used") -> Not Used
A30: Sales | B30: CurrencyRate | D30: =COUNTIF('DWH Tables Metadata'!$B$5:$B$99,B30)>0 -> FALSE | E30: =IF(D30=TRUE,"Used","Not Used") -> Not Used
A31: Sales | B31: SalesTaxRate | D31: =COUNTIF('DWH Tables Metadata'!$B$5:$B$99,B31)>0 -> FALSE | E31: =IF(D31=TRUE,"Used","Not Used") -> Not Used
A32: Sales | B32: SalesTerritoryHistory | D32: =COUNTIF('DWH Tables Metadata'!$B$5:$B$99,B32)>0 -> FALSE | E32: =IF(D32=TRUE,"Used","Not Used") -> Not Used
A33: Sales | B33: Store | C33: s. | D33: =COUNTIF('DWH Tables Metadata'!$B$5:$B$99,B33)>0 -> TRUE | E33: =IF(D33=TRUE,"Used","Not Used") -> Used
A34: Sales | B34: Customer | C34: c. | D34: =COUNTIF('DWH Tables Metadata'!$B$5:$B$99,B34)>0 -> TRUE | E34: =IF(D34=TRUE,"Used","Not Used") -> Used
A35: Sales | B35: SalesOrderDetail | C35: sod. | D35: =COUNTIF('DWH Tables Metadata'!$B$5:$B$99,B35)>0 -> TRUE | E35: =IF(D35=TRUE,"Used","Not Used") -> Used
A36: Sales | B36: SalesOrderHeader | C36: soh. | D36: =COUNTIF('DWH Tables Metadata'!$B$5:$B$99,B36)>0 -> TRUE | E36: =IF(D36=TRUE,"Used","Not Used") -> Used
A37: Sales | B37: SalesPerson | C37: sp. | D37: =COUNTIF('DWH Tables Metadata'!$B$5:$B$99,B37)>0 -> TRUE | E37: =IF(D37=TRUE,"Used","Not Used") -> Used
A38: Sales | B38: SpecialOffer | D38: =COUNTIF('DWH Tables Metadata'!$B$5:$B$99,B38)>0 -> FALSE | E38: =IF(D38=TRUE,"Used","Not Used") -> Not Used
A39: Sales | B39: SpecialOfferProduct | D39: =COUNTIF('DWH Tables Metadata'!$B$5:$B$99,B39)>0 -> FALSE | E39: =IF(D39=TRUE,"Used","Not Used") -> Not Used
G41: HumanResources | H41: Employee | I41: =VLOOKUP(H41,$B$4:$B$37,1,FALSE) -> #N/A
...

Sheet DWH Tables Metadata
A1: Derived from OLTP Tables | C1: Input: DWH Tables | H1: Derived from DWH Tables | J1: Output
A3: OLTP Schema Name | B3: OLTP Table Name | C3: OLTP Table Abbr. | D3: OLTP ColumnName | E3: DWH AliasColumnName | G3: ColumnDescription | H3: Unique Used Tables | J3: Output Columns Declaration Expression | K3: Output Table Declaration Expression
A4: DimAddress | C4: DimAddress | H4: DimAddress | J4: DimAddress
A5: =INDEX('OLTP Tables'!$A$3:$A$39,MATCH(SUBSTITUTE('DWH Tables Metadata'!C5,",",""),'OLTP Tables'!$C$3:$C$39,0)) -> Person | B5: =INDEX('OLTP Tables'!$B$3:$B$39,MATCH(SUBSTITUTE('DWH Tables Metadata'!C5,",",""),'OLTP Tables'!$C$3:$C$39,0)) -> Address | C5: ad. | D5: AddressID | E5: AS | F5: AddressID | H5: {=_xlfn.UNIQUE(A5:B18)} -> Person | I5: Address | J5: =_xlfn.CONCAT( "('",B5,"','",D5,"',","'",F5,"','",G5,"')") -> ('Address','AddressID','AddressID','') | K5: =_xlfn.CONCAT( "('",H5,"','",I5,"')") -> ('Person','Address')
A6: =INDEX('OLTP Tables'!$A$3:$A$39,MATCH(SUBSTITUTE('DWH Tables Metadata'!C6,",",""),'OLTP Tables'!$C$3:$C$39,0)) -> Person | B6: =INDEX('OLTP Tables'!$B$3:$B$39,MATCH(SUBSTITUTE('DWH Tables Metadata'!C6,",",""),'OLTP Tables'!$C$3:$C$39,0)) -> StateProvince | C6: ,spr. | D6: StateProvinceID | E6: AS | F6: StateProvinceID | H6: Person | I6: StateProvince | J6: =_xlfn.CONCAT( ",('",B6,"','",D6,"',","'",F6,"','",G6,"')") -> ,('StateProvince','StateProvinceID','StateProvinceID','') | K6: =_xlfn.CONCAT( ",('",H6,"','",I6,"')") -> ,('Person','StateProvince')
A7: =INDEX('OLTP Tables'!$A$3:$A$39,MATCH(SUBSTITUTE('DWH Tables Metadata'!C7,",",""),'OLTP Tables'!$C$3:$C$39,0)) -> Person | B7: =INDEX('OLTP Tables'!$B$3:$B$39,MATCH(SUBSTITUTE('DWH Tables Metadata'!C7,",",""),'OLTP Tables'!$C$3:$C$39,0)) -> StateProvince | C7: ,spr. | D7: TerritoryID | E7: AS | F7: TerritoryID | H7: Sales | I7: SalesTerritory | J7: =_xlfn.CONCAT( ",('",B7,"','",D7,"',","'",F7,"','",G7,"')") -> ,('StateProvince','TerritoryID','TerritoryID','') | K7: =_xlfn.CONCAT( ",('",H7,"','",I7,"')") -> ,('Sales','SalesTerritory')
A8: =INDEX('OLTP Tables'!$A$3:$A$39,MATCH(SUBSTITUTE('DWH Tables Metadata'!C8,",",""),'OLTP Tables'!$C$3:$C$39,0)) -> Person | B8: =INDEX('OLTP Tables'!$B$3:$B$39,MATCH(SUBSTITUTE('DWH Tables Metadata'!C8,",",""),'OLTP Tables'!$C$3:$C$39,0)) -> Address | C8: ,ad. | D8: AddressLine1 | E8: AS | F8: AddressLine | H8: Person | I8: CountryRegion | J8: =_xlfn.CONCAT( ",('",B8,"','",D8,"',","'",F8,"','",G8,"')") -> ,('Address','AddressLine1','AddressLine','') | K8: =_xlfn.CONCAT( ",('",H8,"','",I8,"')") -> ,('Person','CountryRegion')
A9: =INDEX('OLTP Tables'!$A$3:$A$39,MATCH(SUBSTITUTE('DWH Tables Metadata'!C9,",",""),'OLTP Tables'!$C$3:$C$39,0)) -> Person | B9: =INDEX('OLTP Tables'!$B$3:$B$39,MATCH(SUBSTITUTE('DWH Tables Metadata'!C9,",",""),'OLTP Tables'!$C$3:$C$39,0)) -> Address | C9: ,ad. | D9: City | E9: AS | F9: City | J9: =_xlfn.CONCAT( ",('",B9,"','",D9,"',","'",F9,"','",G9,"')") -> ,('Address','City','City','')
A10: =INDEX('OLTP Tables'!$A$3:$A$39,MATCH(SUBSTITUTE('DWH Tables Metadata'!C10,",",""),'OLTP Tables'!$C$3:$C$39,0)) -> Person | B10: =INDEX('OLTP Tables'!$B$3:$B$39,MATCH(SUBSTITUTE('DWH Tables Metadata'!C10,",",""),'OLTP Tables'!$C$3:$C$39,0)) -> Address | C10: ,ad. | D10: PostalCode | E10: AS | F10: PostalCode | J10: =_xlfn.CONCAT( ",('",B10,"','",D10,"',","'",F10,"','",G10,"')") -> ,('Address','PostalCode','PostalCode','')
A11: =INDEX('OLTP Tables'!$A$3:$A$39,MATCH(SUBSTITUTE('DWH Tables Metadata'!C11,",",""),'OLTP Tables'!$C$3:$C$39,0)) -> Person | B11: =INDEX('OLTP Tables'!$B$3:$B$39,MATCH(SUBSTITUTE('DWH Tables Metadata'!C11,",",""),'OLTP Tables'!$C$3:$C$39,0)) -> StateProvince | C11: ,spr. | D11: Name | E11: AS | F11: StateProvinceName | J11: =_xlfn.CONCAT( ",('",B11,"','",D11,"',","'",F11,"','",G11,"')") -> ,('StateProvince','Name','StateProvinceName','')
A12: =INDEX('OLTP Tables'!$A$3:$A$39,MATCH(SUBSTITUTE('DWH Tables Metadata'!C12,",",""),'OLTP Tables'!$C$3:$C$39,0)) -> Person | B12: =INDEX('OLTP Tables'!$B$3:$B$39,MATCH(SUBSTITUTE('DWH Tables Metadata'!C12,",",""),'OLTP Tables'!$C$3:$C$39,0)) -> StateProvince | C12: ,spr. | D12: StateProvinceCode | E12: AS | F12: StateProvinceCode | J12: =_xlfn.CONCAT( ",('",B12,"','",D12,"',","'",F12,"','",G12,"')") -> ,('StateProvince','StateProvinceCode','StateProvinceCode','')
A13: =INDEX('OLTP Tables'!$A$3:$A$39,MATCH(SUBSTITUTE('DWH Tables Metadata'!C13,",",""),'OLTP Tables'!$C$3:$C$39,0)) -> Sales | B13: =INDEX('OLTP Tables'!$B$3:$B$39,MATCH(SUBSTITUTE('DWH Tables Metadata'!C13,",",""),'OLTP Tables'!$C$3:$C$39,0)) -> SalesTerritory | C13: ,st. | D13: Name | E13: AS | F13: TerritoryName | J13: =_xlfn.CONCAT( ",('",B13,"','",D13,"',","'",F13,"','",G13,"')") -> ,('SalesTerritory','Name','TerritoryName','')
A14: =INDEX('OLTP Tables'!$A$3:$A$39,MATCH(SUBSTITUTE('DWH Tables Metadata'!C14,",",""),'OLTP Tables'!$C$3:$C$39,0)) -> Person | B14: =INDEX('OLTP Tables'!$B$3:$B$39,MATCH(SUBSTITUTE('DWH Tables Metadata'!C14,",",""),'OLTP Tables'!$C$3:$C$39,0)) -> CountryRegion | C14: ,cr. | D14: Name | E14: AS | F14: CountryRegionName | J14: =_xlfn.CONCAT( ",('",B14,"','",D14,"',","'",F14,"','",G14,"')") -> ,('CountryRegion','Name','CountryRegionName','')
A15: =INDEX('OLTP Tables'!$A$3:$A$39,MATCH(SUBSTITUTE('DWH Tables Metadata'!C15,",",""),'OLTP Tables'!$C$3:$C$39,0)) -> Sales | B15: =INDEX('OLTP Tables'!$B$3:$B$39,MATCH(SUBSTITUTE('DWH Tables Metadata'!C15,",",""),'OLTP Tables'!$C$3:$C$39,0)) -> SalesTerritory | C15: ,st. | D15: CountryRegionCode | E15: AS | F15: CountryRegionCode | J15: =_xlfn.CONCAT( ",('",B15,"','",D15,"',","'",F15,"','",G15,"')") -> ,('SalesTerritory','CountryRegionCode','CountryRegionCode','')
A16: =INDEX('OLTP Tables'!$A$3:$A$39,MATCH(SUBSTITUTE('DWH Tables Metadata'!C16,",",""),'OLTP Tables'!$C$3:$C$39,0)) -> Sales | B16: =INDEX('OLTP Tables'!$B$3:$B$39,MATCH(SUBSTITUTE('DWH Tables Metadata'!C16,",",""),'OLTP Tables'!$C$3:$C$39,0)) -> SalesTerritory | C16: ,st. | D16: [Group] | E16: AS | F16: TerritoryGroup | J16: =_xlfn.CONCAT( ",('",B16,"','",D16,"',","'",F16,"','",G16,"')") -> ,('SalesTerritory','[Group]','TerritoryGroup','')
A17: =INDEX('OLTP Tables'!$A$3:$A$39,MATCH(SUBSTITUTE('DWH Tables Metadata'!C17,",",""),'OLTP Tables'!$C$3:$C$39,0)) -> Person | B17: =INDEX('OLTP Tables'!$B$3:$B$39,MATCH(SUBSTITUTE('DWH Tables Metadata'!C17,",",""),'OLTP Tables'!$C$3:$C$39,0)) -> Address | C17: ,ad. | D17: ValidityDate_Start | E17: AS | F17: ValidityDate_Start | J17: =_xlfn.CONCAT( ",('",B17,"','",D17,"',","'",F17,"','",G17,"')") -> ,('Address','ValidityDate_Start','ValidityDate_Start','')
A18: =INDEX('OLTP Tables'!$A$3:$A$39,MATCH(SUBSTITUTE('DWH Tables Metadata'!C18,",",""),'OLTP Tables'!$C$3:$C$39,0)) -> Person | B18: =INDEX('OLTP Tables'!$B$3:$B$39,MATCH(SUBSTITUTE('DWH Tables Metadata'!C18,",",""),'OLTP Tables'!$C$3:$C$39,0)) -> Address | C18: ,ad. | D18: ValidityDate_End | E18: AS | F18: ValidityDate_End | J18: =_xlfn.CONCAT( ",('",B18,"','",D18,"',","'",F18,"','",G18,"')") -> ,('Address','ValidityDate_End','ValidityDate_End','')
A19: DimCustomer | C19: DimCustomer | H19: DimCustomer | J19: DimCustomer
A20: =INDEX('OLTP Tables'!$A$3:$A$39,MATCH(SUBSTITUTE('DWH Tables Metadata'!C20,",",""),'OLTP Tables'!$C$3:$C$39,0)) -> Sales | B20: =INDEX('OLTP Tables'!$B$3:$B$39,MATCH(SUBSTITUTE('DWH Tables Metadata'!C20,",",""),'OLTP Tables'!$C$3:$C$39,0)) -> Customer | C20: c. | D20: CustomerID | E20: AS | F20: CustomerID | H20: {=_xlfn.UNIQUE(A20:B36)} -> Sales | I20: Customer | J20: =_xlfn.CONCAT( "('",B20,"','",D20,"',","'",F20,"','",G20,"')") -> ('Customer','CustomerID','CustomerID ','') | K20: =_xlfn.CONCAT( "('",H20,"','",I20,"')") -> ('Sales','Customer')
A21: =INDEX('OLTP Tables'!$A$3:$A$39,MATCH(SUBSTITUTE('DWH Tables Metadata'!C21,",",""),'OLTP Tables'!$C$3:$C$39,0)) -> Sales | B21: =INDEX('OLTP Tables'!$B$3:$B$39,MATCH(SUBSTITUTE('DWH Tables Metadata'!C21,",",""),'OLTP Tables'!$C$3:$C$39,0)) -> Customer | C21: ,c. | D21: PersonID | E21: AS | F21: CustomerPersonID | H21: Sales | I21: Store | J21: =_xlfn.CONCAT( ",('",B21,"','",D21,"',","'",F21,"','",G21,"')") -> ,('Customer','PersonID','CustomerPersonID','') | K21: =_xlfn.CONCAT( ",('",H21,"','",I21,"')") -> ,('Sales','Store')
A22: =INDEX('OLTP Tables'!$A$3:$A$39,MATCH(SUBSTITUTE('DWH Tables Metadata'!C22,",",""),'OLTP Tables'!$C$3:$C$39,0)) -> Sales | B22: =INDEX('OLTP Tables'!$B$3:$B$39,MATCH(SUBSTITUTE('DWH Tables Metadata'!C22,",",""),'OLTP Tables'!$C$3:$C$39,0)) -> Customer | C22: ,c. | D22: StoreID | E22: AS | F22: StoreID | H22: Person | I22: Person | J22: =_xlfn.CONCAT( ",('",B22,"','",D22,"',","'",F22,"','",G22,"')") -> ,('Customer','StoreID','StoreID','') | K22: =_xlfn.CONCAT( ",('",H22,"','",I22,"')") -> ,('Person','Person')
A23: =INDEX('OLTP Tables'!$A$3:$A$39,MATCH(SUBSTITUTE('DWH Tables Metadata'!C23,",",""),'OLTP Tables'!$C$3:$C$39,0)) -> Sales | B23: =INDEX('OLTP Tables'!$B$3:$B$39,MATCH(SUBSTITUTE('DWH Tables Metadata'!C23,",",""),'OLTP Tables'!$C$3:$C$39,0)) -> Store | C23: ,s. | D23: SalesPersonID | E23: AS | F23: SalesPersonID | H23: Sales | I23: SalesTerritory | J23: =_xlfn.CONCAT( ",('",B23,"','",D23,"',","'",F23,"','",G23,"')") -> ,('Store','SalesPersonID','SalesPersonID','') | K23: =_xlfn.CONCAT( ",('",H23,"','",I23,"')") -> ,('Sales','SalesTerritory')
A24: =INDEX('OLTP Tables'!$A$3:$A$39,MATCH(SUBSTITUTE('DWH Tables Metadata'!C24,",",""),'OLTP Tables'!$C$3:$C$39,0)) -> Sales | B24: =INDEX('OLTP Tables'!$B$3:$B$39,MATCH(SUBSTITUTE('DWH Tables Metadata'!C24,",",""),'OLTP Tables'!$C$3:$C$39,0)) -> Customer | C24: ,c. | D24: TerritoryID | E24: AS | F24: TerritoryID | H24: Person | I24: CountryRegion | J24: =_xlfn.CONCAT( ",('",B24,"','",D24,"',","'",F24,"','",G24,"')") -> ,('Customer','TerritoryID','TerritoryID','') | K24: =_xlfn.CONCAT( ",('",H24,"','",I24,"')") -> ,('Person','CountryRegion')
A25: =INDEX('OLTP Tables'!$A$3:$A$39,MATCH(SUBSTITUTE('DWH Tables Metadata'!C25,",",""),'OLTP Tables'!$C$3:$C$39,0)) -> Person | B25: =INDEX('OLTP Tables'!$B$3:$B$39,MATCH(SUBSTITUTE('DWH Tables Metadata'!C25,",",""),'OLTP Tables'!$C$3:$C$39,0)) -> Person | C25: ,prs. | D25: PersonType | E25: AS | F25: PersonType | G25: ----Primary type of person: SC = Store Contact, IN = Individual (retail) customer, SP = Sales person, EM = Employee (non-sales), VC = Vendor contact, GC = General contact | J25: =_xlfn.CONCAT( ",('",B25,"','",D25,"',","'",F25,"','",G25,"')") -> ,('Person','PersonType','PersonType','----Primary type of person: SC = Store Contact, IN = Individual (retail) customer, SP = Sales person, EM = Employee (non-sales), VC = Vendor contact, GC = General contact')
A26: =INDEX('OLTP Tables'!$A$3:$A$39,MATCH(SUBSTITUTE('DWH Tables Metadata'!C26,",",""),'OLTP Tables'!$C$3:$C$39,0)) -> Person | B26: =INDEX('OLTP Tables'!$B$3:$B$39,MATCH(SUBSTITUTE('DWH Tables Metadata'!C26,",",""),'OLTP Tables'!$C$3:$C$39,0)) -> Person | C26: ,prs. | D26: Title | E26: AS | F26: Title | J26: =_xlfn.CONCAT( ",('",B26,"','",D26,"',","'",F26,"','",G26,"')") -> ,('Person','Title','Title','')
A27: =INDEX('OLTP Tables'!$A$3:$A$39,MATCH(SUBSTITUTE('DWH Tables Metadata'!C27,",",""),'OLTP Tables'!$C$3:$C$39,0)) -> Person | B27: =INDEX('OLTP Tables'!$B$3:$B$39,MATCH(SUBSTITUTE('DWH Tables Metadata'!C27,",",""),'OLTP Tables'!$C$3:$C$39,0)) -> Person | C27: ,prs. | D27: FirstName | E27: AS | F27: FirstName | J27: =_xlfn.CONCAT( ",('",B27,"','",D27,"',","'",F27,"','",G27,"')") -> ,('Person','FirstName','FirstName','')
A28: =INDEX('OLTP Tables'!$A$3:$A$39,MATCH(SUBSTITUTE('DWH Tables Metadata'!C28,",",""),'OLTP Tables'!$C$3:$C$39,0)) -> Person | B28: =INDEX('OLTP Tables'!$B$3:$B$39,MATCH(SUBSTITUTE('DWH Tables Metadata'!C28,",",""),'OLTP Tables'!$C$3:$C$39,0)) -> Person | C28: ,prs. | D28: MiddleName | E28: AS | F28: MiddleName | J28: =_xlfn.CONCAT( ",('",B28,"','",D28,"',","'",F28,"','",G28,"')") -> ,('Person','MiddleName','MiddleName','')
A29: =INDEX('OLTP Tables'!$A$3:$A$39,MATCH(SUBSTITUTE('DWH Tables Metadata'!C29,",",""),'OLTP Tables'!$C$3:$C$39,0)) -> Person | B29: =INDEX('OLTP Tables'!$B$3:$B$39,MATCH(SUBSTITUTE('DWH Tables Metadata'!C29,",",""),'OLTP Tables'!$C$3:$C$39,0)) -> Person | C29: ,prs. | D29: LastName | E29: AS | F29: LastName | J29: =_xlfn.CONCAT( ",('",B29,"','",D29,"',","'",F29,"','",G29,"')") -> ,('Person','LastName','LastName','')
A30: =INDEX('OLTP Tables'!$A$3:$A$39,MATCH(SUBSTITUTE('DWH Tables Metadata'!C30,",",""),'OLTP Tables'!$C$3:$C$39,0)) -> Sales | B30: =INDEX('OLTP Tables'!$B$3:$B$39,MATCH(SUBSTITUTE('DWH Tables Metadata'!C30,",",""),'OLTP Tables'!$C$3:$C$39,0)) -> Store | C30: ,s. | D30: Name | E30: AS | F30: StoreName | J30: =_xlfn.CONCAT( ",('",B30,"','",D30,"',","'",F30,"','",G30,"')") -> ,('Store','Name','StoreName','')
A31: =INDEX('OLTP Tables'!$A$3:$A$39,MATCH(SUBSTITUTE('DWH Tables Metadata'!C31,",",""),'OLTP Tables'!$C$3:$C$39,0)) -> Sales | B31: =INDEX('OLTP Tables'!$B$3:$B$39,MATCH(SUBSTITUTE('DWH Tables Metadata'!C31,",",""),'OLTP Tables'!$C$3:$C$39,0)) -> SalesTerritory | C31: ,st. | D31: Name | E31: AS | F31: TerritoryName | J31: =_xlfn.CONCAT( ",('",B31,"','",D31,"',","'",F31,"','",G31,"')") -> ,('SalesTerritory','Name','TerritoryName','')
A32: =INDEX('OLTP Tables'!$A$3:$A$39,MATCH(SUBSTITUTE('DWH Tables Metadata'!C32,",",""),'OLTP Tables'!$C$3:$C$39,0)) -> Person | B32: =INDEX('OLTP Tables'!$B$3:$B$39,MATCH(SUBSTITUTE('DWH Tables Metadata'!C32,",",""),'OLTP Tables'!$C$3:$C$39,0)) -> CountryRegion | C32: ,cr. | D32: Name | E32: AS | F32: CountryRegionName | J32: =_xlfn.CONCAT( ",('",B32,"','",D32,"',","'",F32,"','",G32,"')") -> ,('CountryRegion','Name','CountryRegionName','')
A33: =INDEX('OLTP Tables'!$A$3:$A$39,MATCH(SUBSTITUTE('DWH Tables Metadata'!C33,",",""),'OLTP Tables'!$C$3:$C$39,0)) -> Sales | B33: =INDEX('OLTP Tables'!$B$3:$B$39,MATCH(SUBSTITUTE('DWH Tables Metadata'!C33,",",""),'OLTP Tables'!$C$3:$C$39,0)) -> SalesTerritory | C33: ,st. | D33: CountryRegionCode | E33: AS | F33: CountryRegionCode | J33: =_xlfn.CONCAT( ",('",B33,"','",D33,"',","'",F33,"','",G33,"')") -> ,('SalesTerritory','CountryRegionCode','CountryRegionCode','')
A34: =INDEX('OLTP Tables'!$A$3:$A$39,MATCH(SUBSTITUTE('DWH Tables Metadata'!C34,",",""),'OLTP Tables'!$C$3:$C$39,0)) -> Sales | B34: =INDEX('OLTP Tables'!$B$3:$B$39,MATCH(SUBSTITUTE('DWH Tables Metadata'!C34,",",""),'OLTP Tables'!$C$3:$C$39,0)) -> SalesTerritory | C34: ,st. | D34: [Group] | E34: AS | F34: TerritoryGroup | J34: =_xlfn.CONCAT( ",('",B34,"','",D34,"',","'",F34,"','",G34,"')") -> ,('SalesTerritory','[Group]','TerritoryGroup','')
A35: =INDEX('OLTP Tables'!$A$3:$A$39,MATCH(SUBSTITUTE('DWH Tables Metadata'!C35,",",""),'OLTP Tables'!$C$3:$C$39,0)) -> Sales | B35: =INDEX('OLTP Tables'!$B$3:$B$39,MATCH(SUBSTITUTE('DWH Tables Metadata'!C35,",",""),'OLTP Tables'!$C$3:$C$39,0)) -> Customer | C35: ,c. | D35: ValidityDate_Start | E35: AS | F35: ValidityDate_Start | J35: =_xlfn.CONCAT( ",('",B35,"','",D35,"',","'",F35,"','",G35,"')") -> ,('Customer','ValidityDate_Start','ValidityDate_Start','')
A36: =INDEX('OLTP Tables'!$A$3:$A$39,MATCH(SUBSTITUTE('DWH Tables Metadata'!C36,",",""),'OLTP Tables'!$C$3:$C$39,0)) -> Sales | B36: =INDEX('OLTP Tables'!$B$3:$B$39,MATCH(SUBSTITUTE('DWH Tables Metadata'!C36,",",""),'OLTP Tables'!$C$3:$C$39,0)) -> Customer | C36: ,c. | D36: ValidityDate_End | E36: AS | F36: ValidityDate_End | J36: =_xlfn.CONCAT( ",('",B36,"','",D36,"',","'",F36,"','",G36,"')") -> ,('Customer','ValidityDate_End','ValidityDate_End','')
A37: DimProduct | C37: DimProduct | H37: DimProduct | J37: DimProduct
A38: =INDEX('OLTP Tables'!$A$3:$A$39,MATCH(SUBSTITUTE('DWH Tables Metadata'!C38,",",""),'OLTP Tables'!$C$3:$C$39,0)) -> Production | B38: =INDEX('OLTP Tables'!$B$3:$B$39,MATCH(SUBSTITUTE('DWH Tables Metadata'!C38,",",""),'OLTP Tables'!$C$3:$C$39,0)) -> Product | C38: p. | D38: ProductNumber | E38: AS | F38: ProductNumber | H38: {=_xlfn.UNIQUE(A38:B60)} -> Production | I38: Product | J38: =_xlfn.CONCAT( "('",B38,"','",D38,"',","'",F38,"','",G38,"')") -> ('Product','ProductNumber','ProductNumber','') | K38: =_xlfn.CONCAT( "('",H38,"','",I38,"')") -> ('Production','Product')
A39: =INDEX('OLTP Tables'!$A$3:$A$39,MATCH(SUBSTITUTE('DWH Tables Metadata'!C39,",",""),'OLTP Tables'!$C$3:$C$39,0)) -> Production | B39: =INDEX('OLTP Tables'!$B$3:$B$39,MATCH(SUBSTITUTE('DWH Tables Metadata'!C39,",",""),'OLTP Tables'!$C$3:$C$39,0)) -> Product | C39: ,p. | D39: ProductID | E39: AS | F39: ProductID | H39: Production | I39: ProductCategory | J39: =_xlfn.CONCAT( ",('",B39,"','",D39,"',","'",F39,"','",G39,"')") -> ,('Product','ProductID','ProductID','') | K39: =_xlfn.CONCAT( ",('",H39,"','",I39,"')") -> ,('Production','ProductCategory')
A40: =INDEX('OLTP Tables'!$A$3:$A$39,MATCH(SUBSTITUTE('DWH Tables Metadata'!C40,",",""),'OLTP Tables'!$C$3:$C$39,0)) -> Production | B40: =INDEX('OLTP Tables'!$B$3:$B$39,MATCH(SUBSTITUTE('DWH Tables Metadata'!C40,",",""),'OLTP Tables'!$C$3:$C$39,0)) -> ProductCategory | C40: ,pc. | D40: ProductCategoryID | E40: AS | F40: ProductCategoryID | H40: Production | I40: ProductSubcategory | J40: =_xlfn.CONCAT( ",('",B40,"','",D40,"',","'",F40,"','",G40,"')") -> ,('ProductCategory','ProductCategoryID','ProductCategoryID','') | K40: =_xlfn.CONCAT( ",('",H40,"','",I40,"')") -> ,('Production','ProductSubcategory')
A41: =INDEX('OLTP Tables'!$A$3:$A$39,MATCH(SUBSTITUTE('DWH Tables Metadata'!C41,",",""),'OLTP Tables'!$C$3:$C$39,0)) -> Production | B41: =INDEX('OLTP Tables'!$B$3:$B$39,MATCH(SUBSTITUTE('DWH Tables Metadata'!C41,",",""),'OLTP Tables'!$C$3:$C$39,0)) -> ProductSubcategory | C41: ,psc. | D41: ProductSubcategoryID | E41: AS | F41: ProductSubcategoryID | H41: Production | I41: UnitMeasure | J41: =_xlfn.CONCAT( ",('",B41,"','",D41,"',","'",F41,"','",G41,"')") -> ,('ProductSubcategory','ProductSubcategoryID','ProductSubcategoryID','') | K41: =_xlfn.CONCAT( ",('",H41,"','",I41,"')") -> ,('Production','UnitMeasure')
...

Sheet Loading Data MetaData
A1: Input: DWH Tables | C1: Attributes Definition | E1: SCD 1 Generator | L1: SCD 2 Generator | R1: #Temp Table Fileds
A3: Column | B3: SCD Type input | C3: @DimAttributes | D3: @StgAttributes | E3: Unique Column | F3: SCD Type | J3: @SCD1_Filter | K3: @SCD1_UpdateStatement | L3: Unique Column | M3: SCD Type | Q3: @SCD2_Filter
A4: DimAddress | C4: DimAddress | E4: DimAddress | L4: DimAddress | R4: DimAddress
A5: AddressID | B5: Fixed | C5: =A5 -> AddressID | D5: =_xlfn.CONCAT("s.",A5) -> s.AddressID | R5: [AddressID] [int] NOT NULL,
A6: StateProvinceID | B6: Fixed | C6: =_xlfn.CONCAT(",",A6) -> ,StateProvinceID | D6: =_xlfn.CONCAT(",s.",A6) -> ,s.StateProvinceID | R6: [StateProvinceID] [int] NULL,
A7: TerritoryID | B7: Fixed | C7: =_xlfn.CONCAT(",",A7) -> ,TerritoryID | D7: =_xlfn.CONCAT(",s.",A7) -> ,s.TerritoryID | R7: [TerritoryID] [int] NULL,
A8: AddressLine | B8: Fixed | C8: =_xlfn.CONCAT(",",A8) -> ,AddressLine | D8: =_xlfn.CONCAT(",s.",A8) -> ,s.AddressLine | R8: [AddressLine] [nvarchar](120) NULL,
A9: City | B9: Fixed | C9: =_xlfn.CONCAT(",",A9) -> ,City | D9: =_xlfn.CONCAT(",s.",A9) -> ,s.City | R9: [City] [nvarchar](60) NULL,
A10: PostalCode | B10: Fixed | C10: =_xlfn.CONCAT(",",A10) -> ,PostalCode | D10: =_xlfn.CONCAT(",s.",A10) -> ,s.PostalCode | R10: [PostalCode] [nvarchar](30) NULL,
A11: StateProvinceName | B11: Fixed | C11: =_xlfn.CONCAT(",",A11) -> ,StateProvinceName | D11: =_xlfn.CONCAT(",s.",A11) -> ,s.StateProvinceName | R11: [StateProvinceName] [nvarchar](100) NULL,
A12: StateProvinceCode | B12: Fixed | C12: =_xlfn.CONCAT(",",A12) -> ,StateProvinceCode | D12: =_xlfn.CONCAT(",s.",A12) -> ,s.StateProvinceCode | R12: [StateProvinceCode] [nchar](6) NULL,
A13: TerritoryName | B13: Fixed | C13: =_xlfn.CONCAT(",",A13) -> ,TerritoryName | D13: =_xlfn.CONCAT(",s.",A13) -> ,s.TerritoryName | R13: [TerritoryName] [nvarchar](100) NULL,
A14: CountryRegionName | B14: Fixed | C14: =_xlfn.CONCAT(",",A14) -> ,CountryRegionName | D14: =_xlfn.CONCAT(",s.",A14) -> ,s.CountryRegionName | R14: [CountryRegionName] [nvarchar](100) NULL,
A15: CountryRegionCode | B15: Fixed | C15: =_xlfn.CONCAT(",",A15) -> ,CountryRegionCode | D15: =_xlfn.CONCAT(",s.",A15) -> ,s.CountryRegionCode | R15: [CountryRegionCode] [nvarchar](6) NULL,
A16: TerritoryGroup | B16: Fixed | C16: =_xlfn.CONCAT(",",A16) -> ,TerritoryGroup | D16: =_xlfn.CONCAT(",s.",A16) -> ,s.TerritoryGroup | R16: [TerritoryGroup] [nvarchar](100) NULL,
A17: ValidityDate_Start | C17: =_xlfn.CONCAT(",",A17) -> ,ValidityDate_Start | D17: =_xlfn.CONCAT(",s.",A17) -> ,s.ValidityDate_Start | R17: [ValidityDate_Start] [datetime] NULL,
A18: ValidityDate_End | C18: =_xlfn.CONCAT(",",A18) -> ,ValidityDate_End | D18: =_xlfn.CONCAT(",s.",A18) -> ,s.ValidityDate_End | R18: [ValidityDate_End] [datetime] NULL,
A19: DimCustomer | C19: DimCustomer | E19: DimCustomer | L19: DimCustomer | R19: DimCustomer
A20: CustomerID | B20: Fixed | C20: =A20 -> CustomerID | D20: =_xlfn.CONCAT("s.",A20) -> s.CustomerID | E20: {=_xlfn.UNIQUE(_xlfn._xlws.FILTER(A20:A36, (B20:B36=1) + (B20:B36="Fixed")))} -> CustomerID | F20: =_xlfn.XLOOKUP(E20,$A$20:$A$36,$B$20:$B$36,"",0) -> Fixed | G20: =_xlfn.CONCAT("d.",E20) -> d.CustomerID | H20: =IF(F20="Fixed","=","<>") -> = | I20: =_xlfn.CONCAT("s.",E20) -> s.CustomerID | J20: =IF(AND(F19<>"Fixed", F20="Fixed"),_xlfn.CONCAT("' ",G20, " ", H20, " ", I20), IF(AND(F19="Fixed", F20="Fixed"),_xlfn.CONCAT("and ", G20, " ", H20, " ", I20), IF(AND(F19="Fixed", F20=1),_xlfn.CONCAT( "and ( ",G20, " ", H20, " ", I20), IF(AND(F19=1, F20=1,F21 = 1),_xlfn.CONCAT( "or ",G20, " ", H20, " ", I20), IF(AND(F19=1, F20=1,F21 <> 1),_xlfn.CONCAT( "or ",G20, " ", H20, " ", I20, " ) '") ))))) -> ' d.CustomerID = s.CustomerID | K20: {=_xlfn.TEXTJOIN(_xlfn.CONCAT(CHAR(10)," ,"), FALSE,_xlfn.ANCHORARRAY( E20) & " = " & I20:I31)} -> CustomerID = s.CustomerID ,CustomerPersonID = s.CustomerPersonID ,PersonType = s.PersonType ,StoreID = s.StoreID ,SalesPersonID = s.SalesPersonID ,TerritoryID = s.TerritoryID ,Title = s.Title ,StoreName = s.StoreName ,TerritoryName = s.TerritoryName ,CountryRegionName = s.CountryRegionName ,CountryRegionCode = s.CountryRegionCode ,TerritoryGroup = s.TerritoryGroup | L20: {=_xlfn.UNIQUE(_xlfn._xlws.FILTER(A20:A36, (B20:B36=2) + (B20:B36="Fixed")))} -> CustomerID | M20: =_xlfn.XLOOKUP(L20,$A$20:$A$36,$B$20:$B$36,"",0) -> Fixed | N20: =_xlfn.CONCAT("d.",L20) -> d.CustomerID | O20: =IF(M20="Fixed","=","<>") -> = | P20: =_xlfn.CONCAT("s.",L20) -> s.CustomerID | Q20: =IF(AND(M19<>"Fixed", M20="Fixed"),_xlfn.CONCAT("' ",N20, " ", O20, " ", P20), IF(AND(M19="Fixed", M20="Fixed"),_xlfn.CONCAT("and ", N20, " ", O20, " ", P20), IF(AND(M19="Fixed", M20=2),_xlfn.CONCAT( "and ( ",N20, " ", O20, " ", P20), IF(AND(M19=2, M20=2,M21 = 2),_xlfn.CONCAT( "or ",N20, " ", O20, " ", P20), IF(AND(M19=2, M20=2,M21 <> 2),_xlfn.CONCAT( "or ",N20, " ", O20, " ", P20, " ) '") ))))) -> ' d.CustomerID = s.CustomerID | R20: [CustomerID] [int] NOT NULL,
A21: CustomerPersonID | B21: Fixed | C21: =_xlfn.CONCAT(",",A21) -> ,CustomerPersonID | D21: =_xlfn.CONCAT(",s.",A21) -> ,s.CustomerPersonID | E21: CustomerPersonID | F21: =_xlfn.XLOOKUP(E21,$A$20:$A$36,$B$20:$B$36,"",0) -> Fixed | G21: =_xlfn.CONCAT("d.",E21) -> d.CustomerPersonID | H21: =IF(F21="Fixed","=","<>") -> = | I21: =_xlfn.CONCAT("s.",E21) -> s.CustomerPersonID | J21: =IF(AND(F20<>"Fixed", F21="Fixed"),_xlfn.CONCAT("' ",G21, " ", H21, " ", I21), IF(AND(F20="Fixed", F21="Fixed"),_xlfn.CONCAT("and ", G21, " ", H21, " ", I21), IF(AND(F20="Fixed", F21=1),_xlfn.CONCAT( "and ( ",G21, " ", H21, " ", I21), IF(AND(F20=1, F21=1,F22 = 1),_xlfn.CONCAT( "or ",G21, " ", H21, " ", I21), IF(AND(F20=1, F21=1,F22 <> 1),_xlfn.CONCAT( "or ",G21, " ", H21, " ", I21, " ) '") ))))) -> and d.CustomerPersonID = s.CustomerPersonID | L21: CustomerPersonID | M21: =_xlfn.XLOOKUP(L21,$A$20:$A$36,$B$20:$B$36,"",0) -> Fixed | N21: =_xlfn.CONCAT("d.",L21) -> d.CustomerPersonID | O21: =IF(M21="Fixed","=","<>") -> = | P21: =_xlfn.CONCAT("s.",L21) -> s.CustomerPersonID | Q21: =IF(AND(M20<>"Fixed", M21="Fixed"),_xlfn.CONCAT("' ",N21, " ", O21, " ", P21), IF(AND(M20="Fixed", M21="Fixed"),_xlfn.CONCAT("and ", N21, " ", O21, " ", P21), IF(AND(M20="Fixed", M21=2),_xlfn.CONCAT( "and ( ",N21, " ", O21, " ", P21), IF(AND(M20=2, M21=2,M22 = 2),_xlfn.CONCAT( "or ",N21, " ", O21, " ", P21), IF(AND(M20=2, M21=2,M22 <> 2),_xlfn.CONCAT( "or ",N21, " ", O21, " ", P21, " ) '") ))))) -> and d.CustomerPersonID = s.CustomerPersonID | R21: [CustomerPersonID] [int] NULL,
A22: PersonType | B22: Fixed | C22: =_xlfn.CONCAT(",",A22) -> ,PersonType | D22: =_xlfn.CONCAT(",s.",A22) -> ,s.PersonType | E22: PersonType | F22: =_xlfn.XLOOKUP(E22,$A$20:$A$36,$B$20:$B$36,"",0) -> Fixed | G22: =_xlfn.CONCAT("d.",E22) -> d.PersonType | H22: =IF(F22="Fixed","=","<>") -> = | I22: =_xlfn.CONCAT("s.",E22) -> s.PersonType | J22: =IF(AND(F21<>"Fixed", F22="Fixed"),_xlfn.CONCAT("' ",G22, " ", H22, " ", I22), IF(AND(F21="Fixed", F22="Fixed"),_xlfn.CONCAT("and ", G22, " ", H22, " ", I22), IF(AND(F21="Fixed", F22=1),_xlfn.CONCAT( "and ( ",G22, " ", H22, " ", I22), IF(AND(F21=1, F22=1,F23 = 1),_xlfn.CONCAT( "or ",G22, " ", H22, " ", I22), IF(AND(F21=1, F22=1,F23 <> 1),_xlfn.CONCAT( "or ",G22, " ", H22, " ", I22, " ) '") ))))) -> and d.PersonType = s.PersonType | L22: PersonType | M22: =_xlfn.XLOOKUP(L22,$A$20:$A$36,$B$20:$B$36,"",0) -> Fixed | N22: =_xlfn.CONCAT("d.",L22) -> d.PersonType | O22: =IF(M22="Fixed","=","<>") -> = | P22: =_xlfn.CONCAT("s.",L22) -> s.PersonType | Q22: =IF(AND(M21<>"Fixed", M22="Fixed"),_xlfn.CONCAT("' ",N22, " ", O22, " ", P22), IF(AND(M21="Fixed", M22="Fixed"),_xlfn.CONCAT("and ", N22, " ", O22, " ", P22), IF(AND(M21="Fixed", M22=2),_xlfn.CONCAT( "and ( ",N22, " ", O22, " ", P22), IF(AND(M21=2, M22=2,M23 = 2),_xlfn.CONCAT( "or ",N22, " ", O22, " ", P22), IF(AND(M21=2, M22=2,M23 <> 2),_xlfn.CONCAT( "or ",N22, " ", O22, " ", P22, " ) '") ))))) -> and d.PersonType = s.PersonType | R22: [PersonType] [nchar](4) NULL,
A23: StoreID | B23: 1 | C23: =_xlfn.CONCAT(",",A23) -> ,StoreID | D23: =_xlfn.CONCAT(",s.",A23) -> ,s.StoreID | E23: StoreID | F23: =_xlfn.XLOOKUP(E23,$A$20:$A$36,$B$20:$B$36,"",0) -> 1 | G23: =_xlfn.CONCAT("d.",E23) -> d.StoreID | H23: =IF(F23="Fixed","=","<>") -> <> | I23: =_xlfn.CONCAT("s.",E23) -> s.StoreID | J23: =IF(AND(F22<>"Fixed", F23="Fixed"),_xlfn.CONCAT("' ",G23, " ", H23, " ", I23), IF(AND(F22="Fixed", F23="Fixed"),_xlfn.CONCAT("and ", G23, " ", H23, " ", I23), IF(AND(F22="Fixed", F23=1),_xlfn.CONCAT( "and ( ",G23, " ", H23, " ", I23), IF(AND(F22=1, F23=1,F24 = 1),_xlfn.CONCAT( "or ",G23, " ", H23, " ", I23), IF(AND(F22=1, F23=1,F24 <> 1),_xlfn.CONCAT( "or ",G23, " ", H23, " ", I23, " ) '") ))))) -> and ( d.StoreID <> s.StoreID | L23: FirstName | M23: =_xlfn.XLOOKUP(L23,$A$20:$A$36,$B$20:$B$36,"",0) -> 2 | N23: =_xlfn.CONCAT("d.",L23) -> d.FirstName | O23: =IF(M23="Fixed","=","<>") -> <> | P23: =_xlfn.CONCAT("s.",L23) -> s.FirstName | Q23: =IF(AND(M22<>"Fixed", M23="Fixed"),_xlfn.CONCAT("' ",N23, " ", O23, " ", P23), IF(AND(M22="Fixed", M23="Fixed"),_xlfn.CONCAT("and ", N23, " ", O23, " ", P23), IF(AND(M22="Fixed", M23=2),_xlfn.CONCAT( "and ( ",N23, " ", O23, " ", P23), IF(AND(M22=2, M23=2,M24 = 2),_xlfn.CONCAT( "or ",N23, " ", O23, " ", P23), IF(AND(M22=2, M23=2,M24 <> 2),_xlfn.CONCAT( "or ",N23, " ", O23, " ", P23, " ) '") ))))) -> and ( d.FirstName <> s.FirstName | R23: [StoreID] [int] NULL,
A24: SalesPersonID | B24: 1 | C24: =_xlfn.CONCAT(",",A24) -> ,SalesPersonID | D24: =_xlfn.CONCAT(",s.",A24) -> ,s.SalesPersonID | E24: SalesPersonID | F24: =_xlfn.XLOOKUP(E24,$A$20:$A$36,$B$20:$B$36,"",0) -> 1 | G24: =_xlfn.CONCAT("d.",E24) -> d.SalesPersonID | H24: =IF(F24="Fixed","=","<>") -> <> | I24: =_xlfn.CONCAT("s.",E24) -> s.SalesPersonID | J24: =IF(AND(F23<>"Fixed", F24="Fixed"),_xlfn.CONCAT("' ",G24, " ", H24, " ", I24), IF(AND(F23="Fixed", F24="Fixed"),_xlfn.CONCAT("and ", G24, " ", H24, " ", I24), IF(AND(F23="Fixed", F24=1),_xlfn.CONCAT( "and ( ",G24, " ", H24, " ", I24), IF(AND(F23=1, F24=1,F25 = 1),_xlfn.CONCAT( "or ",G24, " ", H24, " ", I24), IF(AND(F23=1, F24=1,F25 <> 1),_xlfn.CONCAT( "or ",G24, " ", H24, " ", I24, " ) '") ))))) -> or d.SalesPersonID <> s.SalesPersonID | L24: MiddleName | M24: =_xlfn.XLOOKUP(L24,$A$20:$A$36,$B$20:$B$36,"",0) -> 2 | N24: =_xlfn.CONCAT("d.",L24) -> d.MiddleName | O24: =IF(M24="Fixed","=","<>") -> <> | P24: =_xlfn.CONCAT("s.",L24) -> s.MiddleName | Q24: =IF(AND(M23<>"Fixed", M24="Fixed"),_xlfn.CONCAT("' ",N24, " ", O24, " ", P24), IF(AND(M23="Fixed", M24="Fixed"),_xlfn.CONCAT("and ", N24, " ", O24, " ", P24), IF(AND(M23="Fixed", M24=2),_xlfn.CONCAT( "and ( ",N24, " ", O24, " ", P24), IF(AND(M23=2, M24=2,M25 = 2),_xlfn.CONCAT( "or ",N24, " ", O24, " ", P24), IF(AND(M23=2, M24=2,M25 <> 2),_xlfn.CONCAT( "or ",N24, " ", O24, " ", P24, " ) '") ))))) -> or d.MiddleName <> s.MiddleName | R24: [SalesPersonID] [int] NULL,
A25: TerritoryID | B25: 1 | C25: =_xlfn.CONCAT(",",A25) -> ,TerritoryID | D25: =_xlfn.CONCAT(",s.",A25) -> ,s.TerritoryID | E25: TerritoryID | F25: =_xlfn.XLOOKUP(E25,$A$20:$A$36,$B$20:$B$36,"",0) -> 1 | G25: =_xlfn.CONCAT("d.",E25) -> d.TerritoryID | H25: =IF(F25="Fixed","=","<>") -> <> | I25: =_xlfn.CONCAT("s.",E25) -> s.TerritoryID | J25: =IF(AND(F24<>"Fixed", F25="Fixed"),_xlfn.CONCAT("' ",G25, " ", H25, " ", I25), IF(AND(F24="Fixed", F25="Fixed"),_xlfn.CONCAT("and ", G25, " ", H25, " ", I25), IF(AND(F24="Fixed", F25=1),_xlfn.CONCAT( "and ( ",G25, " ", H25, " ", I25), IF(AND(F24=1, F25=1,F26 = 1),_xlfn.CONCAT( "or ",G25, " ", H25, " ", I25), IF(AND(F24=1, F25=1,F26 <> 1),_xlfn.CONCAT( "or ",G25, " ", H25, " ", I25, " ) '") ))))) -> or d.TerritoryID <> s.TerritoryID | L25: LastName | M25: =_xlfn.XLOOKUP(L25,$A$20:$A$36,$B$20:$B$36,"",0) -> 2 | N25: =_xlfn.CONCAT("d.",L25) -> d.LastName | O25: =IF(M25="Fixed","=","<>") -> <> | P25: =_xlfn.CONCAT("s.",L25) -> s.LastName | Q25: =IF(AND(M24<>"Fixed", M25="Fixed"),_xlfn.CONCAT("' ",N25, " ", O25, " ", P25), IF(AND(M24="Fixed", M25="Fixed"),_xlfn.CONCAT("and ", N25, " ", O25, " ", P25), IF(AND(M24="Fixed", M25=2),_xlfn.CONCAT( "and ( ",N25, " ", O25, " ", P25), IF(AND(M24=2, M25=2,M26 = 2),_xlfn.CONCAT( "or ",N25, " ", O25, " ", P25), IF(AND(M24=2, M25=2,M26 <> 2),_xlfn.CONCAT( "or ",N25, " ", O25, " ", P25, " ) '") ))))) -> or d.LastName <> s.LastName ) ' | R25: [TerritoryID] [int] NULL,
A26: Title | B26: 1 | C26: =_xlfn.CONCAT(",",A26) -> ,Title | D26: =_xlfn.CONCAT(",s.",A26) -> ,s.Title | E26: Title | F26: =_xlfn.XLOOKUP(E26,$A$20:$A$36,$B$20:$B$36,"",0) -> 1 | G26: =_xlfn.CONCAT("d.",E26) -> d.Title | H26: =IF(F26="Fixed","=","<>") -> <> | I26: =_xlfn.CONCAT("s.",E26) -> s.Title | J26: =IF(AND(F25<>"Fixed", F26="Fixed"),_xlfn.CONCAT("' ",G26, " ", H26, " ", I26), IF(AND(F25="Fixed", F26="Fixed"),_xlfn.CONCAT("and ", G26, " ", H26, " ", I26), IF(AND(F25="Fixed", F26=1),_xlfn.CONCAT( "and ( ",G26, " ", H26, " ", I26), IF(AND(F25=1, F26=1,F27 = 1),_xlfn.CONCAT( "or ",G26, " ", H26, " ", I26), IF(AND(F25=1, F26=1,F27 <> 1),_xlfn.CONCAT( "or ",G26, " ", H26, " ", I26, " ) '") ))))) -> or d.Title <> s.Title | R26: [Title] [nvarchar](16) NULL,
A27: FirstName | B27: 2 | C27: =_xlfn.CONCAT(",",A27) -> ,FirstName | D27: =_xlfn.CONCAT(",s.",A27) -> ,s.FirstName | E27: StoreName | F27: =_xlfn.XLOOKUP(E27,$A$20:$A$36,$B$20:$B$36,"",0) -> 1 | G27: =_xlfn.CONCAT("d.",E27) -> d.StoreName | H27: =IF(F27="Fixed","=","<>") -> <> | I27: =_xlfn.CONCAT("s.",E27) -> s.StoreName | J27: =IF(AND(F26<>"Fixed", F27="Fixed"),_xlfn.CONCAT("' ",G27, " ", H27, " ", I27), IF(AND(F26="Fixed", F27="Fixed"),_xlfn.CONCAT("and ", G27, " ", H27, " ", I27), IF(AND(F26="Fixed", F27=1),_xlfn.CONCAT( "and ( ",G27, " ", H27, " ", I27), IF(AND(F26=1, F27=1,F28 = 1),_xlfn.CONCAT( "or ",G27, " ", H27, " ", I27), IF(AND(F26=1, F27=1,F28 <> 1),_xlfn.CONCAT( "or ",G27, " ", H27, " ", I27, " ) '") ))))) -> or d.StoreName <> s.StoreName | R27: [FirstName] [nvarchar](100) NULL,
A28: MiddleName | B28: 2 | C28: =_xlfn.CONCAT(",",A28) -> ,MiddleName | D28: =_xlfn.CONCAT(",s.",A28) -> ,s.MiddleName | E28: TerritoryName | F28: =_xlfn.XLOOKUP(E28,$A$20:$A$36,$B$20:$B$36,"",0) -> 1 | G28: =_xlfn.CONCAT("d.",E28) -> d.TerritoryName | H28: =IF(F28="Fixed","=","<>") -> <> | I28: =_xlfn.CONCAT("s.",E28) -> s.TerritoryName | J28: =IF(AND(F27<>"Fixed", F28="Fixed"),_xlfn.CONCAT("' ",G28, " ", H28, " ", I28), IF(AND(F27="Fixed", F28="Fixed"),_xlfn.CONCAT("and ", G28, " ", H28, " ", I28), IF(AND(F27="Fixed", F28=1),_xlfn.CONCAT( "and ( ",G28, " ", H28, " ", I28), IF(AND(F27=1, F28=1,F29 = 1),_xlfn.CONCAT( "or ",G28, " ", H28, " ", I28), IF(AND(F27=1, F28=1,F29 <> 1),_xlfn.CONCAT( "or ",G28, " ", H28, " ", I28, " ) '") ))))) -> or d.TerritoryName <> s.TerritoryName | R28: [MiddleName] [nvarchar](100) NULL,
A29: LastName | B29: 2 | C29: =_xlfn.CONCAT(",",A29) -> ,LastName | D29: =_xlfn.CONCAT(",s.",A29) -> ,s.LastName | E29: CountryRegionName | F29: =_xlfn.XLOOKUP(E29,$A$20:$A$36,$B$20:$B$36,"",0) -> 1 | G29: =_xlfn.CONCAT("d.",E29) -> d.CountryRegionName | H29: =IF(F29="Fixed","=","<>") -> <> | I29: =_xlfn.CONCAT("s.",E29) -> s.CountryRegionName | J29: =IF(AND(F28<>"Fixed", F29="Fixed"),_xlfn.CONCAT("' ",G29, " ", H29, " ", I29), IF(AND(F28="Fixed", F29="Fixed"),_xlfn.CONCAT("and ", G29, " ", H29, " ", I29), IF(AND(F28="Fixed", F29=1),_xlfn.CONCAT( "and ( ",G29, " ", H29, " ", I29), IF(AND(F28=1, F29=1,F30 = 1),_xlfn.CONCAT( "or ",G29, " ", H29, " ", I29), IF(AND(F28=1, F29=1,F30 <> 1),_xlfn.CONCAT( "or ",G29, " ", H29, " ", I29, " ) '") ))))) -> or d.CountryRegionName <> s.CountryRegionName | R29: [LastName] [nvarchar](100) NULL,
A30: StoreName | B30: 1 | C30: =_xlfn.CONCAT(",",A30) -> ,StoreName | D30: =_xlfn.CONCAT(",s.",A30) -> ,s.StoreName | E30: CountryRegionCode | F30: =_xlfn.XLOOKUP(E30,$A$20:$A$36,$B$20:$B$36,"",0) -> 1 | G30: =_xlfn.CONCAT("d.",E30) -> d.CountryRegionCode | H30: =IF(F30="Fixed","=","<>") -> <> | I30: =_xlfn.CONCAT("s.",E30) -> s.CountryRegionCode | J30: =IF(AND(F29<>"Fixed", F30="Fixed"),_xlfn.CONCAT("' ",G30, " ", H30, " ", I30), IF(AND(F29="Fixed", F30="Fixed"),_xlfn.CONCAT("and ", G30, " ", H30, " ", I30), IF(AND(F29="Fixed", F30=1),_xlfn.CONCAT( "and ( ",G30, " ", H30, " ", I30), IF(AND(F29=1, F30=1,F31 = 1),_xlfn.CONCAT( "or ",G30, " ", H30, " ", I30), IF(AND(F29=1, F30=1,F31 <> 1),_xlfn.CONCAT( "or ",G30, " ", H30, " ", I30, " ) '") ))))) -> or d.CountryRegionCode <> s.CountryRegionCode | R30: [StoreName] [nvarchar](100) NULL,
A31: TerritoryName | B31: 1 | C31: =_xlfn.CONCAT(",",A31) -> ,TerritoryName | D31: =_xlfn.CONCAT(",s.",A31) -> ,s.TerritoryName | E31: TerritoryGroup | F31: =_xlfn.XLOOKUP(E31,$A$20:$A$36,$B$20:$B$36,"",0) -> 1 | G31: =_xlfn.CONCAT("d.",E31) -> d.TerritoryGroup | H31: =IF(F31="Fixed","=","<>") -> <> | I31: =_xlfn.CONCAT("s.",E31) -> s.TerritoryGroup | J31: =IF(AND(F30<>"Fixed", F31="Fixed"),_xlfn.CONCAT("' ",G31, " ", H31, " ", I31), IF(AND(F30="Fixed", F31="Fixed"),_xlfn.CONCAT("and ", G31, " ", H31, " ", I31), IF(AND(F30="Fixed", F31=1),_xlfn.CONCAT( "and ( ",G31, " ", H31, " ", I31), IF(AND(F30=1, F31=1,F32 = 1),_xlfn.CONCAT( "or ",G31, " ", H31, " ", I31), IF(AND(F30=1, F31=1,F32 <> 1),_xlfn.CONCAT( "or ",G31, " ", H31, " ", I31, " ) '") ))))) -> or d.TerritoryGroup <> s.TerritoryGroup ) ' | R31: [TerritoryName] [nvarchar](100) NULL,
A32: CountryRegionName | B32: 1 | C32: =_xlfn.CONCAT(",",A32) -> ,CountryRegionName | D32: =_xlfn.CONCAT(",s.",A32) -> ,s.CountryRegionName | R32: [CountryRegionName] [nvarchar](100) NULL,
A33: CountryRegionCode | B33: 1 | C33: =_xlfn.CONCAT(",",A33) -> ,CountryRegionCode | D33: =_xlfn.CONCAT(",s.",A33) -> ,s.CountryRegionCode | R33: [CountryRegionCode] [nvarchar](6) NULL,
A34: TerritoryGroup | B34: 1 | C34: =_xlfn.CONCAT(",",A34) -> ,TerritoryGroup | D34: =_xlfn.CONCAT(",s.",A34) -> ,s.TerritoryGroup | R34: [TerritoryGroup] [nvarchar](100) NULL,
A35: ValidityDate_Start | C35: =_xlfn.CONCAT(",",A35) -> ,ValidityDate_Start | D35: =_xlfn.CONCAT(",s.",A35) -> ,s.ValidityDate_Start | R35: [ValidityDate_Start] [datetime] NULL,
A36: ValidityDate_End | C36: =_xlfn.CONCAT(",",A36) -> ,ValidityDate_End | D36: =_xlfn.CONCAT(",s.",A36) -> ,s.ValidityDate_End | R36: [ValidityDate_End] [datetime] NULL,
A37: DimProduct | C37: DimProduct | E37: DimProduct | L37: DimProduct | R37: DimProduct
A38: ProductNumber | B38: Fixed | C38: =A38 -> ProductNumber | D38: =_xlfn.CONCAT("s.",A38) -> s.ProductNumber | E38: {=_xlfn.UNIQUE(_xlfn._xlws.FILTER(A38:A60, (B38:B60=1) + (B38:B60="Fixed")))} -> ProductNumber | F38: =_xlfn.XLOOKUP(E38,$A$38:$A$60,$B$38:$B$60,"",0) -> Fixed | G38: =_xlfn.CONCAT("d.",E38) -> d.ProductNumber | H38: =IF(F38="Fixed","=","<>") -> = | I38: =_xlfn.CONCAT("s.",E38) -> s.ProductNumber | J38: =IF(AND(F37<>"Fixed", F38="Fixed"),_xlfn.CONCAT("' ",G38, " ", H38, " ", I38), IF(AND(F37="Fixed", F38="Fixed"),_xlfn.CONCAT("and ", G38, " ", H38, " ", I38), IF(AND(F37="Fixed", F38=1),_xlfn.CONCAT( "and ( ",G38, " ", H38, " ", I38), IF(AND(F37=1, F38=1,F39 = 1),_xlfn.CONCAT( "or ",G38, " ", H38, " ", I38), IF(AND(F37=1, F38=1,F39 <> 1),_xlfn.CONCAT( "or ",G38, " ", H38, " ", I38, " ) '") ))))) -> ' d.ProductNumber = s.ProductNumber | K38: {=_xlfn.TEXTJOIN(_xlfn.CONCAT(CHAR(10)," ,"), FALSE,_xlfn.ANCHORARRAY( E38) & " = " & I38:I52)} -> ProductNumber = s.ProductNumber ,ProductID = s.ProductID ,ProductCategoryID = s.ProductCategoryID ,ProductSubcategoryID = s.ProductSubcategoryID ,UnitSizeCode = s.UnitSizeCode ,UnitWeightCode = s.UnitWeightCode ,ProductName = s.ProductName ,ProductCategoryName = s.ProductCategoryName ,ProductSubcategoryName = s.ProductSubcategoryName ,ProductSize = s.ProductSize ,UnitSizeName = s.UnitSizeName ,UnitWeightName = s.UnitWeightName ,SellStartDate = s.SellStartDate ,SellEndDate = s.SellEndDate ,DiscountinuedDate = s.DiscountinuedDate | L38: {=_xlfn.UNIQUE(_xlfn._xlws.FILTER(A38:A60, (B38:B60=2) + (B38:B60="Fixed")))} -> ProductNumber | M38: =_xlfn.XLOOKUP(L38,$A$38:$A$60,$B$38:$B$60,"",0) -> Fixed | N38: =_xlfn.CONCAT("d.",L38) -> d.ProductNumber | O38: =IF(M38="Fixed","=","<>") -> = | P38: =_xlfn.CONCAT("s.",L38) -> s.ProductNumber | Q38: =IF(AND(M37<>"Fixed", M38="Fixed"),_xlfn.CONCAT("' ",N38, " ", O38, " ", P38), IF(AND(M37="Fixed", M38="Fixed"),_xlfn.CONCAT("and ", N38, " ", O38, " ", P38), IF(AND(M37="Fixed", M38=2),_xlfn.CONCAT( "and ( ",N38, " ", O38, " ", P38), IF(AND(M37=2, M38=2,M39 = 2),_xlfn.CONCAT( "or ",N38, " ", O38, " ", P38), IF(AND(M37=2, M38=2,M39 <> 2),_xlfn.CONCAT( "or ",N38, " ", O38, " ", P38, " ) '") ))))) -> ' d.ProductNumber = s.ProductNumber | R38: [ProductNumber] [nvarchar](50) NULL,
A39: ProductID | B39: Fixed | C39: =_xlfn.CONCAT(",",A39) -> ,ProductID | D39: =_xlfn.CONCAT(",s.",A39) -> ,s.ProductID | E39: ProductID | F39: =_xlfn.XLOOKUP(E39,$A$38:$A$60,$B$38:$B$60,"",0) -> Fixed | G39: =_xlfn.CONCAT("d.",E39) -> d.ProductID | H39: =IF(F39="Fixed","=","<>") -> = | I39: =_xlfn.CONCAT("s.",E39) -> s.ProductID | J39: =IF(AND(F38<>"Fixed", F39="Fixed"),_xlfn.CONCAT("' ",G39, " ", H39, " ", I39), IF(AND(F38="Fixed", F39="Fixed"),_xlfn.CONCAT("and ", G39, " ", H39, " ", I39), IF(AND(F38="Fixed", F39=1),_xlfn.CONCAT( "and ( ",G39, " ", H39, " ", I39), IF(AND(F38=1, F39=1,F40 = 1),_xlfn.CONCAT( "or ",G39, " ", H39, " ", I39), IF(AND(F38=1, F39=1,F40 <> 1),_xlfn.CONCAT( "or ",G39, " ", H39, " ", I39, " ) '") ))))) -> and d.ProductID = s.ProductID | L39: ProductID | M39: =_xlfn.XLOOKUP(L39,$A$38:$A$60,$B$38:$B$60,"",0) -> Fixed | N39: =_xlfn.CONCAT("d.",L39) -> d.ProductID | O39: =IF(M39="Fixed","=","<>") -> = | P39: =_xlfn.CONCAT("s.",L39) -> s.ProductID | Q39: =IF(AND(M38<>"Fixed", M39="Fixed"),_xlfn.CONCAT("' ",N39, " ", O39, " ", P39), IF(AND(M38="Fixed", M39="Fixed"),_xlfn.CONCAT("and ", N39, " ", O39, " ", P39), IF(AND(M38="Fixed", M39=2),_xlfn.CONCAT( "and ( ",N39, " ", O39, " ", P39), IF(AND(M38=2, M39=2,M40 = 2),_xlfn.CONCAT( "or ",N39, " ", O39, " ", P39), IF(AND(M38=2, M39=2,M40 <> 2),_xlfn.CONCAT( "or ",N39, " ", O39, " ", P39, " ) '") ))))) -> and d.ProductID = s.ProductID | R39: [ProductID] [int] NOT NULL,
A40: ProductCategoryID | B40: Fixed | C40: =_xlfn.CONCAT(",",A40) -> ,ProductCategoryID | D40: =_xlfn.CONCAT(",s.",A40) -> ,s.ProductCategoryID | E40: ProductCategoryID | F40: =_xlfn.XLOOKUP(E40,$A$38:$A$60,$B$38:$B$60,"",0) -> Fixed | G40: =_xlfn.CONCAT("d.",E40) -> d.ProductCategoryID | H40: =IF(F40="Fixed","=","<>") -> = | I40: =_xlfn.CONCAT("s.",E40) -> s.ProductCategoryID | J40: =IF(AND(F39<>"Fixed", F40="Fixed"),_xlfn.CONCAT("' ",G40, " ", H40, " ", I40), IF(AND(F39="Fixed", F40="Fixed"),_xlfn.CONCAT("and ", G40, " ", H40, " ", I40), IF(AND(F39="Fixed", F40=1),_xlfn.CONCAT( "and ( ",G40, " ", H40, " ", I40), IF(AND(F39=1, F40=1,F41 = 1),_xlfn.CONCAT( "or ",G40, " ", H40, " ", I40), IF(AND(F39=1, F40=1,F41 <> 1),_xlfn.CONCAT( "or ",G40, " ", H40, " ", I40, " ) '") ))))) -> and d.ProductCategoryID = s.ProductCategoryID | L40: ProductCategoryID | M40: =_xlfn.XLOOKUP(L40,$A$38:$A$60,$B$38:$B$60,"",0) -> Fixed | N40: =_xlfn.CONCAT("d.",L40) -> d.ProductCategoryID | O40: =IF(M40="Fixed","=","<>") -> = | P40: =_xlfn.CONCAT("s.",L40) -> s.ProductCategoryID | Q40: =IF(AND(M39<>"Fixed", M40="Fixed"),_xlfn.CONCAT("' ",N40, " ", O40, " ", P40), IF(AND(M39="Fixed", M40="Fixed"),_xlfn.CONCAT("and ", N40, " ", O40, " ", P40), IF(AND(M39="Fixed", M40=2),_xlfn.CONCAT( "and ( ",N40, " ", O40, " ", P40), IF(AND(M39=2, M40=2,M41 = 2),_xlfn.CONCAT( "or ",N40, " ", O40, " ", P40), IF(AND(M39=2, M40=2,M41 <> 2),_xlfn.CONCAT( "or ",N40, " ", O40, " ", P40, " ) '") ))))) -> and d.ProductCategoryID = s.ProductCategoryID | R40: [ProductCategoryID] [int] NULL,
A41: ProductSubcategoryID | B41: Fixed | C41: =_xlfn.CONCAT(",",A41) -> ,ProductSubcategoryID | D41: =_xlfn.CONCAT(",s.",A41) -> ,s.ProductSubcategoryID | E41: ProductSubcategoryID | F41: =_xlfn.XLOOKUP(E41,$A$38:$A$60,$B$38:$B$60,"",0) -> Fixed | G41: =_xlfn.CONCAT("d.",E41) -> d.ProductSubcategoryID | H41: =IF(F41="Fixed","=","<>") -> = | I41: =_xlfn.CONCAT("s.",E41) -> s.ProductSubcategoryID | J41: =IF(AND(F40<>"Fixed", F41="Fixed"),_xlfn.CONCAT("' ",G41, " ", H41, " ", I41), IF(AND(F40="Fixed", F41="Fixed"),_xlfn.CONCAT("and ", G41, " ", H41, " ", I41), IF(AND(F40="Fixed", F41=1),_xlfn.CONCAT( "and ( ",G41, " ", H41, " ", I41), IF(AND(F40=1, F41=1,F42 = 1),_xlfn.CONCAT( "or ",G41, " ", H41, " ", I41), IF(AND(F40=1, F41=1,F42 <> 1),_xlfn.CONCAT( "or ",G41, " ", H41, " ", I41, " ) '") ))))) -> and d.ProductSubcategoryID = s.ProductSubcategoryID | L41: ProductSubcategoryID | M41: =_xlfn.XLOOKUP(L41,$A$38:$A$60,$B$38:$B$60,"",0) -> Fixed | N41: =_xlfn.CONCAT("d.",L41) -> d.ProductSubcategoryID | O41: =IF(M41="Fixed","=","<>") -> = | P41: =_xlfn.CONCAT("s.",L41) -> s.ProductSubcategoryID | Q41: =IF(AND(M40<>"Fixed", M41="Fixed"),_xlfn.CONCAT("' ",N41, " ", O41, " ", P41), IF(AND(M40="Fixed", M41="Fixed"),_xlfn.CONCAT("and ", N41, " ", O41, " ", P41), IF(AND(M40="Fixed", M41=2),_xlfn.CONCAT( "and ( ",N41, " ", O41, " ", P41), IF(AND(M40=2, M41=2,M44 = 2),_xlfn.CONCAT( "or ",N41, " ", O41, " ", P41), IF(AND(M40=2, M41=2,M44 <> 2),_xlfn.CONCAT( "or ",N41, " ", O41, " ", P41, " ) '") ))))) -> and d.ProductSubcategoryID = s.ProductSubcategoryID | R41: [ProductSubcategoryID] [int] NULL,
...
